<?xml version="1.0" ?>
<!-- =================================================================================== -->
<!-- |    This document was autogenerated by xacro from rover.xacro                    | -->
<!-- |    EDITING THIS FILE BY HAND IS NOT RECOMMENDED                                 | -->
<!-- =================================================================================== -->
<robot name="robot">
  <!-- width  (y) -->
  <!-- wheel thickness -->
  <!-- wheel y offset (left/right) -->
  <!-- Half height of rover -->
  <!-- wheel -->
  <!-- Dark blue -->
  <!-- ========== BASE FOOTPRINT ========== -->
  <link name="base_footprint"/>
  <!-- ========== BASE TO FOOTPRINT JOINT ========== -->
  <joint name="base_joint" type="fixed">
    <parent link="base_footprint"/>
    <child link="base_link"/>
    <origin rpy="0 0 0" xyz="0 0 0.10522000000000001"/>
  </joint>
  <!-- ========== BASE LINK ========== -->
  <link name="base_link">
    <visual>
      <origin rpy="0 0 0" xyz="0 0 0"/>
      <geometry>
        <box size="0.55663 0.388 0.14044"/>
      </geometry>
      <material name="body_material">
        <color rgba="0.8 0.2 0.2 1.0"/>
      </material>
    </visual>
    <collision>
      <origin rpy="0 0 0" xyz="0 0 0"/>
      <geometry>
        <box size="0.55663 0.388 0.14044"/>
      </geometry>
    </collision>
    <inertial>
      <origin rpy="0 0 0" xyz="0 0 0"/>
      <mass value="82.19746927345601"/>
      <inertia ixx="1.1662957378089533" ixy="0.0" ixz="0.0" iyy="2.257418898664428" iyz="0.0" izz="3.153512463239335"/>
    </inertial>
  </link>
  <!-- ============================================================== -->
  <!-- WHEELS (Using ROS Convention: +X=Front, +Y=Left, +Z=Up)        -->
  <!-- ============================================================== -->
  <!-- ========== FRONT LEFT WHEEL ========== -->
  <joint name="front_left_wheel_joint" type="continuous">
    <parent link="base_link"/>
    <child link="front_left_wheel"/>
    <origin rpy="0 0 0" xyz="0.24331499999999998 0.214 -0.07022"/>
    <axis xyz="0 1 0"/>
    <limit effort="50.0" velocity="10.0"/>
    <dynamics damping="0.1" friction="0.1"/>
  </joint>
  <link name="front_left_wheel">
    <visual>
      <origin rpy="1.5708 0 0" xyz="0 0 0"/>
      <geometry>
        <cylinder length="0.04" radius="0.035"/>
      </geometry>
      <material name="wheel_material">
        <color rgba="0.2 0.2 0.2 1.0"/>
      </material>
    </visual>
    <collision>
      <origin rpy="1.5708 0 0" xyz="0 0 0"/>
      <geometry>
        <cylinder length="0.04" radius="0.035"/>
      </geometry>
    </collision>
    <inertial>
      <origin rpy="1.5708 0 0" xyz="0 0 0"/>
      <mass value="0.41717208799350014"/>
      <inertia ixx="0.0002555179038960189" ixy="0.0" ixz="0.0" iyy="0.00018338189701380946" iyz="0.0" izz="0.00018338189701380946"/>
    </inertial>
  </link>
  <!-- ========== FRONT RIGHT WHEEL ========== -->
  <joint name="front_right_wheel_joint" type="continuous">
    <parent link="base_link"/>
    <child link="front_right_wheel"/>
    <origin rpy="0 0 0" xyz="0.24331499999999998 -0.214 -0.07022"/>
    <axis xyz="0 1 0"/>
    <limit effort="50.0" velocity="10.0"/>
    <dynamics damping="0.1" friction="0.1"/>
  </joint>
  <link name="front_right_wheel">
    <visual>
      <origin rpy="1.5708 0 0" xyz="0 0 0"/>
      <geometry>
        <cylinder length="0.04" radius="0.035"/>
      </geometry>
      <material name="wheel_material">
        <color rgba="0.2 0.2 0.2 1.0"/>
      </material>
    </visual>
    <collision>
      <origin rpy="1.5708 0 0" xyz="0 0 0"/>
      <geometry>
        <cylinder length="0.04" radius="0.035"/>
      </geometry>
    </collision>
    <inertial>
      <origin rpy="1.5708 0 0" xyz="0 0 0"/>
      <mass value="0.41717208799350014"/>
      <inertia ixx="0.0002555179038960189" ixy="0.0" ixz="0.0" iyy="0.00018338189701380946" iyz="0.0" izz="0.00018338189701380946"/>
    </inertial>
  </link>
  <!-- ========== REAR LEFT WHEEL ========== -->
  <joint name="rear_left_wheel_joint" type="continuous">
    <parent link="base_link"/>
    <child link="rear_left_wheel"/>
    <origin rpy="0 0 0" xyz="-0.24331499999999998 0.214 -0.07022"/>
    <axis xyz="0 1 0"/>
    <limit effort="50.0" velocity="10.0"/>
    <dynamics damping="0.1" friction="0.1"/>
  </joint>
  <link name="rear_left_wheel">
    <visual>
      <origin rpy="1.5708 0 0" xyz="0 0 0"/>
      <geometry>
        <cylinder length="0.04" radius="0.035"/>
      </geometry>
      <material name="wheel_material">
        <color rgba="0.2 0.2 0.2 1.0"/>
      </material>
    </visual>
    <collision>
      <origin rpy="1.5708 0 0" xyz="0 0 0"/>
      <geometry>
        <cylinder length="0.04" radius="0.035"/>
      </geometry>
    </collision>
    <inertial>
      <origin rpy="1.5708 0 0" xyz="0 0 0"/>
      <mass value="0.41717208799350014"/>
      <inertia ixx="0.0002555179038960189" ixy="0.0" ixz="0.0" iyy="0.00018338189701380946" iyz="0.0" izz="0.00018338189701380946"/>
    </inertial>
  </link>
  <!-- ========== REAR RIGHT WHEEL ========== -->
  <joint name="rear_right_wheel_joint" type="continuous">
    <parent link="base_link"/>
    <child link="rear_right_wheel"/>
    <origin rpy="0 0 0" xyz="-0.24331499999999998 -0.214 -0.07022"/>
    <axis xyz="0 1 0"/>
    <limit effort="50.0" velocity="10.0"/>
    <dynamics damping="0.1" friction="0.1"/>
  </joint>
  <link name="rear_right_wheel">
    <visual>
      <origin rpy="1.5708 0 0" xyz="0 0 0"/>
      <geometry>
        <cylinder length="0.04" radius="0.035"/>
      </geometry>
      <material name="wheel_material">
        <color rgba="0.2 0.2 0.2 1.0"/>
      </material>
    </visual>
    <collision>
      <origin rpy="1.5708 0 0" xyz="0 0 0"/>
      <geometry>
        <cylinder length="0.04" radius="0.035"/>
      </geometry>
    </collision>
    <inertial>
      <origin rpy="1.5708 0 0" xyz="0 0 0"/>
      <mass value="0.41717208799350014"/>
      <inertia ixx="0.0002555179038960189" ixy="0.0" ixz="0.0" iyy="0.00018338189701380946" iyz="0.0" izz="0.00018338189701380946"/>
    </inertial>
  </link>
  <!-- ============================================================== -->
  <!-- RPI CAMERA - MOUNTED ON FRONT FACE LOOKING FORWARD            -->
  <!-- ============================================================== -->
  <!-- Camera mount joint (physical camera on front face) -->
  <joint name="camera_joint" type="fixed">
    <parent link="base_link"/>
    <child link="camera_link"/>
    <origin rpy="0 1.5708 0" xyz="0.278315 0 0.03511"/>
  </joint>
  <!-- Camera physical link -->
  <link name="camera_link">
    <visual>
      <origin rpy="0 0 0" xyz="0 0 0"/>
      <geometry>
        <box size="0.025 0.025 0.009"/>
      </geometry>
      <material name="camera_material">
        <color rgba="0.1 0.1 0.3 1.0"/>
      </material>
    </visual>
    <collision>
      <origin rpy="0 0 0" xyz="0 0 0"/>
      <geometry>
        <box size="0.025 0.025 0.009"/>
      </geometry>
    </collision>
    <inertial>
      <mass value="0.003"/>
      <origin rpy="0 0 0" xyz="0 0 0"/>
      <inertia ixx="0.000001" ixy="0" ixz="0" iyy="0.000001" iyz="0" izz="0.000001"/>
    </inertial>
  </link>
  <!-- Optical frame joint (for camera sensor) -->
  <!-- This represents the actual camera sensor frame looking forward -->
  <!-- rpy="0 -1.5708 0" rotates camera to look forward (+X direction) -->
  <!-- Then rpy="-1.5708 0 -1.5708" aligns Z forward for optical convention -->
  <joint name="camera_optical_joint" type="fixed">
    <parent link="camera_link"/>
    <child link="camera_optical_frame"/>
    <origin rpy="-1.5708 0 -1.5708" xyz="0 0 0.0045"/>
  </joint>
  <!-- Optical frame link -->
  <!-- This follows REP-103/REP-104 standard for camera frames -->
  <!-- Z is forward (optical axis), X is right, Y is down -->
  <link name="camera_optical_frame"/>
  <!-- ============================================================== -->
  <!-- LIDAR (Optional)                                              -->
  <!-- ============================================================== -->
  <joint name="lidar_joint" type="fixed">
    <origin rpy="0 0 0" xyz="0 0 0.07022"/>
    <parent link="base_link"/>
    <child link="lidar_link"/>
  </joint>
  <link name="lidar_link">
    <visual>
      <origin rpy="0 0 0" xyz="0 0 0"/>
      <geometry>
        <cylinder length="0.1" radius="0.05"/>
      </geometry>
    </visual>
    <collision>
      <origin rpy="0 0 0" xyz="0 0 0"/>
      <geometry>
        <cylinder length="0.1" radius="0.05"/>
      </geometry>
    </collision>
    <inertial>
      <mass value="0.1"/>
      <origin rpy="0 0 0" xyz="0 0 0"/>
      <inertia ixx="0.0001" ixy="0" ixz="0" iyy="0.0001" iyz="0" izz="0.0001"/>
    </inertial>
  </link>
</robot>
