<?xml version="1.0" ?>
<!-- =================================================================================== -->
<!-- |    This document was autogenerated by xacro from /home/waseemanwar/rover_ws/install/rover_description/share/rover_description/urdf/rover.xacro | -->
<!-- |    EDITING THIS FILE BY HAND IS NOT RECOMMENDED                                 | -->
<!-- =================================================================================== -->
<robot name="robot">
  <!-- width  (y) -->
  <!-- wheel thickness -->
  <!-- wheel y offset (left/right) -->
  <!-- Half height of rover -->
  <!-- wheel -->
  <!-- Satin Black -->
  <!-- Dark Gunmetal -->
  <!-- Bold Premium Blue -->
  <!-- Premium Silver -->
  <!-- ========== BASE ========== -->
  <link name="base_footprint"/>
  <joint name="base_joint" type="fixed">
    <parent link="base_footprint"/>
    <child link="base_link"/>
    <origin rpy="0 0 0" xyz="0 0 0.10522000000000001"/>
  </joint>
  <!-- ========== BASE LINK ========== -->
  <link name="base_link">
    <visual>
      <origin rpy="0 0 0" xyz="0 0 0"/>
      <geometry>
        <box size="0.55663 0.388 0.14044"/>
      </geometry>
      <material name="body_material">
        <color rgba="0.02 0.02 0.02 1.0"/>
      </material>
    </visual>
    <collision>
      <origin rpy="0 0 0" xyz="0 0 0"/>
      <geometry>
        <box size="0.55663 0.388 0.14044"/>
      </geometry>
    </collision>
    <inertial>
      <origin rpy="0 0 0" xyz="0 0 0"/>
      <mass value="82.19746927345601"/>
      <inertia ixx="1.1662957378089533" ixy="0.0" ixz="0.0" iyy="2.257418898664428" iyz="0.0" izz="3.153512463239335"/>
    </inertial>
  </link>
  <!-- ============================================================== -->
  <!-- WHEELS                                                         -->
  <!-- ============================================================== -->
  <!-- FRONT LEFT WHEEL -->
  <joint name="front_left_wheel_joint" type="continuous">
    <parent link="base_link"/>
    <child link="front_left_wheel"/>
    <origin rpy="0 0 0" xyz="0.24331499999999998 0.214 -0.07022"/>
    <axis xyz="0 1 0"/>
    <limit effort="50.0" velocity="10.0"/>
    <dynamics damping="0.1" friction="0.1"/>
  </joint>
  <link name="front_left_wheel">
    <visual name="tire">
      <origin rpy="1.5708 0 0" xyz="0 0 0"/>
      <geometry>
        <cylinder length="0.04" radius="0.035"/>
      </geometry>
      <material name="wheel_material">
        <color rgba="0.08 0.08 0.08 1.0"/>
      </material>
    </visual>
    <visual name="rim">
      <origin rpy="1.5708 0 0" xyz="0 0 0"/>
      <geometry>
        <cylinder length="0.042" radius="0.022750000000000003"/>
      </geometry>
      <material name="wheel_rim_material">
        <color rgba="0.85 0.85 0.88 1.0"/>
      </material>
    </visual>
    <collision>
      <origin rpy="1.5708 0 0" xyz="0 0 0"/>
      <geometry>
        <cylinder length="0.04" radius="0.035"/>
      </geometry>
    </collision>
    <inertial>
      <origin rpy="1.5708 0 0" xyz="0 0 0"/>
      <mass value="0.41717208799350014"/>
      <inertia ixx="0.0002555179038960189" ixy="0.0" ixz="0.0" iyy="0.00018338189701380946" iyz="0.0" izz="0.00018338189701380946"/>
    </inertial>
  </link>
  <!-- FRONT RIGHT WHEEL -->
  <joint name="front_right_wheel_joint" type="continuous">
    <parent link="base_link"/>
    <child link="front_right_wheel"/>
    <origin rpy="0 0 0" xyz="0.24331499999999998 -0.214 -0.07022"/>
    <axis xyz="0 1 0"/>
    <limit effort="50.0" velocity="10.0"/>
    <dynamics damping="0.1" friction="0.1"/>
  </joint>
  <link name="front_right_wheel">
    <visual name="tire">
      <origin rpy="1.5708 0 0" xyz="0 0 0"/>
      <geometry>
        <cylinder length="0.04" radius="0.035"/>
      </geometry>
      <material name="wheel_material">
        <color rgba="0.08 0.08 0.08 1.0"/>
      </material>
    </visual>
    <visual name="rim">
      <origin rpy="1.5708 0 0" xyz="0 0 0"/>
      <geometry>
        <cylinder length="0.042" radius="0.022750000000000003"/>
      </geometry>
      <material name="wheel_rim_material">
        <color rgba="0.85 0.85 0.88 1.0"/>
      </material>
    </visual>
    <collision>
      <origin rpy="1.5708 0 0" xyz="0 0 0"/>
      <geometry>
        <cylinder length="0.04" radius="0.035"/>
      </geometry>
    </collision>
    <inertial>
      <origin rpy="1.5708 0 0" xyz="0 0 0"/>
      <mass value="0.41717208799350014"/>
      <inertia ixx="0.0002555179038960189" ixy="0.0" ixz="0.0" iyy="0.00018338189701380946" iyz="0.0" izz="0.00018338189701380946"/>
    </inertial>
  </link>
  <!-- REAR LEFT WHEEL -->
  <joint name="rear_left_wheel_joint" type="continuous">
    <parent link="base_link"/>
    <child link="rear_left_wheel"/>
    <origin rpy="0 0 0" xyz="-0.24331499999999998 0.214 -0.07022"/>
    <axis xyz="0 1 0"/>
    <limit effort="50.0" velocity="10.0"/>
    <dynamics damping="0.1" friction="0.1"/>
  </joint>
  <link name="rear_left_wheel">
    <visual name="tire">
      <origin rpy="1.5708 0 0" xyz="0 0 0"/>
      <geometry>
        <cylinder length="0.04" radius="0.035"/>
      </geometry>
      <material name="wheel_material">
        <color rgba="0.08 0.08 0.08 1.0"/>
      </material>
    </visual>
    <visual name="rim">
      <origin rpy="1.5708 0 0" xyz="0 0 0"/>
      <geometry>
        <cylinder length="0.042" radius="0.022750000000000003"/>
      </geometry>
      <material name="wheel_rim_material">
        <color rgba="0.85 0.85 0.88 1.0"/>
      </material>
    </visual>
    <collision>
      <origin rpy="1.5708 0 0" xyz="0 0 0"/>
      <geometry>
        <cylinder length="0.04" radius="0.035"/>
      </geometry>
    </collision>
    <inertial>
      <origin rpy="1.5708 0 0" xyz="0 0 0"/>
      <mass value="0.41717208799350014"/>
      <inertia ixx="0.0002555179038960189" ixy="0.0" ixz="0.0" iyy="0.00018338189701380946" iyz="0.0" izz="0.00018338189701380946"/>
    </inertial>
  </link>
  <!-- REAR RIGHT WHEEL -->
  <joint name="rear_right_wheel_joint" type="continuous">
    <parent link="base_link"/>
    <child link="rear_right_wheel"/>
    <origin rpy="0 0 0" xyz="-0.24331499999999998 -0.214 -0.07022"/>
    <axis xyz="0 1 0"/>
    <limit effort="50.0" velocity="10.0"/>
    <dynamics damping="0.1" friction="0.1"/>
  </joint>
  <link name="rear_right_wheel">
    <visual name="tire">
      <origin rpy="1.5708 0 0" xyz="0 0 0"/>
      <geometry>
        <cylinder length="0.04" radius="0.035"/>
      </geometry>
      <material name="wheel_material">
        <color rgba="0.08 0.08 0.08 1.0"/>
      </material>
    </visual>
    <visual name="rim">
      <origin rpy="1.5708 0 0" xyz="0 0 0"/>
      <geometry>
        <cylinder length="0.042" radius="0.022750000000000003"/>
      </geometry>
      <material name="wheel_rim_material">
        <color rgba="0.85 0.85 0.88 1.0"/>
      </material>
    </visual>
    <collision>
      <origin rpy="1.5708 0 0" xyz="0 0 0"/>
      <geometry>
        <cylinder length="0.04" radius="0.035"/>
      </geometry>
    </collision>
    <inertial>
      <origin rpy="1.5708 0 0" xyz="0 0 0"/>
      <mass value="0.41717208799350014"/>
      <inertia ixx="0.0002555179038960189" ixy="0.0" ixz="0.0" iyy="0.00018338189701380946" iyz="0.0" izz="0.00018338189701380946"/>
    </inertial>
  </link>
  <!-- ============================================================== -->
  <!-- RPI CAMERA                                                     -->
  <!-- ============================================================== -->
  <joint name="camera_joint" type="fixed">
    <parent link="base_link"/>
    <child link="camera_link"/>
    <origin rpy="0 1.5708 0" xyz="0.278315 0 0.03511"/>
  </joint>
  <link name="camera_link">
    <visual>
      <origin rpy="0 0 0" xyz="0 0 0"/>
      <geometry>
        <box size="0.025 0.025 0.009"/>
      </geometry>
      <material name="camera_material">
        <color rgba="0.05 0.25 0.65 1.0"/>
      </material>
    </visual>
    <collision>
      <origin rpy="0 0 0" xyz="0 0 0"/>
      <geometry>
        <box size="0.025 0.025 0.009"/>
      </geometry>
    </collision>
    <inertial>
      <mass value="0.003"/>
      <origin rpy="0 0 0" xyz="0 0 0"/>
      <inertia ixx="0.000001" ixy="0" ixz="0" iyy="0.000001" iyz="0" izz="0.000001"/>
    </inertial>
  </link>
  <joint name="camera_optical_joint" type="fixed">
    <parent link="camera_link"/>
    <child link="camera_optical_frame"/>
    <origin rpy="-1.5708 0 -1.5708" xyz="0 0 0.0045"/>
  </joint>
  <link name="camera_optical_frame"/>
  <!-- ============================================================== -->
  <!-- RPLIDAR A1 - FIXED HEIGHT                                      -->
  <!-- ============================================================== -->
  <!-- ============================================================== -->
  <!-- RPLIDAR A1 - CORRECTED HEIGHT                                  -->
  <!-- ============================================================== -->
  <!-- Lidar joint - mounted higher -->
  <!-- ============================================================== -->
  <!-- RPLIDAR A1 - CORRECTED: NOT HOVERING, RAYS FROM MIDDLE        -->
  <!-- ============================================================== -->
  <!-- Lidar joint - mounted just above the rover body -->
  <joint name="lidar_joint" type="fixed">
    <origin rpy="0 0 0" xyz="0 0 0.08522"/>
    <!-- Just above body -->
    <parent link="base_link"/>
    <child link="lidar_link"/>
  </joint>
  <!-- Lidar visual -->
  <link name="lidar_link">
    <visual name="lidar_body">
      <origin rpy="0 0 0" xyz="0 0 0"/>
      <geometry>
        <cylinder length="0.042" radius="0.048"/>
      </geometry>
      <material name="lidar_material">
        <color rgba="0.35 0.05 0.08 1.0"/>
      </material>
    </visual>
    <visual name="lidar_top">
      <origin rpy="0 0 0" xyz="0 0 0.016"/>
      <geometry>
        <cylinder length="0.005" radius="0.03"/>
      </geometry>
      <material name="lidar_top_material">
        <color rgba="0.12 0.12 0.12 1.0"/>
      </material>
    </visual>
    <collision>
      <origin rpy="0 0 0" xyz="0 0 0"/>
      <geometry>
        <cylinder length="0.042" radius="0.048"/>
      </geometry>
    </collision>
    <inertial>
      <mass value="0.17"/>
      <origin rpy="0 0 0" xyz="0 0 0"/>
      <inertia ixx="0.0001" ixy="0" ixz="0" iyy="0.0001" iyz="0" izz="0.0001"/>
    </inertial>
  </link>
  <!-- ============================================================== -->
  <!-- GAZEBO LIDAR SENSOR - RAYS FROM MIDDLE OF LIDAR               -->
  <!-- ============================================================== -->
  <gazebo reference="lidar_link">
    <sensor name="gpu_lidar" type="gpu_lidar">
      <!-- Rays from the center of the lidar (NOT the top) -->
      <pose>0 0 0.0105 0 0 0</pose>
      <always_on>true</always_on>
      <visualize>true</visualize>
      <update_rate>10</update_rate>
      <topic>scan</topic>
      <lidar>
        <scan>
          <horizontal>
            <samples>720</samples>
            <resolution>1</resolution>
            <min_angle>-3.14159</min_angle>
            <max_angle>3.14159</max_angle>
          </horizontal>
          <vertical>
            <samples>1</samples>
            <resolution>0.01</resolution>
            <min_angle>0</min_angle>
            <max_angle>0</max_angle>
          </vertical>
        </scan>
        <range>
          <min>0.05</min>
          <max>12.0</max>
          <resolution>0.01</resolution>
        </range>
        <noise>
          <type>gaussian</type>
          <mean>0.0</mean>
          <stddev>0.001</stddev>
        </noise>
      </lidar>
    </sensor>
  </gazebo>
  <!-- ============================================================== -->
  <!-- GAZEBO CONFIGURATIONS                                          -->
  <!-- ============================================================== -->
  <gazebo reference="front_left_wheel">
    <mu1>0.8</mu1>
    <mu2>0.05</mu2>
    <kp>1000000.0</kp>
    <kd>100.0</kd>
    <minDepth>0.001</minDepth>
    <material>Gazebo/DarkGrey</material>
  </gazebo>
  <gazebo reference="front_right_wheel">
    <mu1>0.8</mu1>
    <mu2>0.05</mu2>
    <kp>1000000.0</kp>
    <kd>100.0</kd>
    <minDepth>0.001</minDepth>
    <material>Gazebo/DarkGrey</material>
  </gazebo>
  <gazebo reference="rear_left_wheel">
    <mu1>0.8</mu1>
    <mu2>0.05</mu2>
    <kp>1000000.0</kp>
    <kd>100.0</kd>
    <minDepth>0.001</minDepth>
    <material>Gazebo/DarkGrey</material>
  </gazebo>
  <gazebo reference="rear_right_wheel">
    <mu1>0.8</mu1>
    <mu2>0.05</mu2>
    <kp>1000000.0</kp>
    <kd>100.0</kd>
    <minDepth>0.001</minDepth>
    <material>Gazebo/DarkGrey</material>
  </gazebo>
  <gazebo reference="base_link">
    <mu1>0.2</mu1>
    <mu2>0.2</mu2>
    <material>Gazebo/Black</material>
  </gazebo>
  <!-- ============================================================== -->
  <!-- SENSORS SYSTEM PLUGIN                                         -->
  <!-- ============================================================== -->
  <gazebo>
    <plugin filename="gz-sim-sensors-system" name="gz::sim::systems::Sensors">
      <render_engine>ogre2</render_engine>
    </plugin>
  </gazebo>
</robot>
